<?xml version="1.0" encoding="UTF-8"?>
<testng-results skipped="0" failed="1" total="2" passed="1">
  <reporter-output>
  </reporter-output>
  <suite name="Default suite" duration-ms="85" started-at="2014-09-01T14:24:30Z" finished-at="2014-09-01T14:24:30Z">
    <groups>
    </groups>
    <test name="Default test" duration-ms="85" started-at="2014-09-01T14:24:30Z" finished-at="2014-09-01T14:24:30Z">
      <class name="hu.rbandee.chess.pieces.PawnTest">
        <test-method status="PASS" signature="stay_in_same_place_is_invalid_move()[pri:0, instance:hu.rbandee.chess.pieces.PawnTest@24f454e4]" name="stay_in_same_place_is_invalid_move" duration-ms="37" started-at="2014-09-01T16:24:30Z" finished-at="2014-09-01T16:24:30Z">
          <reporter-output>
          </reporter-output>
        </test-method> <!-- stay_in_same_place_is_invalid_move -->
        <test-method status="FAIL" signature="step_one_step_forward_is_valid_move()[pri:0, instance:hu.rbandee.chess.pieces.PawnTest@24f454e4]" name="step_one_step_forward_is_valid_move" duration-ms="4" started-at="2014-09-01T16:24:30Z" finished-at="2014-09-01T16:24:30Z">
          <exception class="java.lang.AssertionError">
            <message>
              <![CDATA[expected [false] but found [true]]]>
            </message>
            <full-stacktrace>
              <![CDATA[java.lang.AssertionError: expected [false] but found [true]
	at org.testng.Assert.fail(Assert.java:94)
	at org.testng.Assert.failNotEquals(Assert.java:494)
	at org.testng.Assert.assertEquals(Assert.java:123)
	at org.testng.Assert.assertEquals(Assert.java:286)
	at org.testng.Assert.assertEquals(Assert.java:296)
	at hu.rbandee.chess.pieces.PawnTest.step_one_step_forward_is_valid_move(PawnTest.java:20)
	at sun.reflect.NativeMethodAccessorImpl.invoke0(Native Method)
	at sun.reflect.NativeMethodAccessorImpl.invoke(Unknown Source)
	at sun.reflect.DelegatingMethodAccessorImpl.invoke(Unknown Source)
	at java.lang.reflect.Method.invoke(Unknown Source)
	at org.testng.internal.MethodInvocationHelper.invokeMethod(MethodInvocationHelper.java:84)
	at org.testng.internal.Invoker.invokeMethod(Invoker.java:714)
	at org.testng.internal.Invoker.invokeTestMethod(Invoker.java:901)
	at org.testng.internal.Invoker.invokeTestMethods(Invoker.java:1231)
	at org.testng.internal.TestMethodWorker.invokeTestMethods(TestMethodWorker.java:127)
	at org.testng.internal.TestMethodWorker.run(TestMethodWorker.java:111)
	at org.testng.TestRunner.privateRun(TestRunner.java:767)
	at org.testng.TestRunner.run(TestRunner.java:617)
	at org.testng.SuiteRunner.runTest(SuiteRunner.java:334)
	at org.testng.SuiteRunner.runSequentially(SuiteRunner.java:329)
	at org.testng.SuiteRunner.privateRun(SuiteRunner.java:291)
	at org.testng.SuiteRunner.run(SuiteRunner.java:240)
	at org.testng.SuiteRunnerWorker.runSuite(SuiteRunnerWorker.java:52)
	at org.testng.SuiteRunnerWorker.run(SuiteRunnerWorker.java:86)
	at org.testng.TestNG.runSuitesSequentially(TestNG.java:1224)
	at org.testng.TestNG.runSuitesLocally(TestNG.java:1149)
	at org.testng.TestNG.run(TestNG.java:1057)
	at org.testng.remote.RemoteTestNG.run(RemoteTestNG.java:111)
	at org.testng.remote.RemoteTestNG.initAndRun(RemoteTestNG.java:204)
	at org.testng.remote.RemoteTestNG.main(RemoteTestNG.java:175)
]]>
            </full-stacktrace>
          </exception> <!-- java.lang.AssertionError -->
          <reporter-output>
          </reporter-output>
        </test-method> <!-- step_one_step_forward_is_valid_move -->
      </class> <!-- hu.rbandee.chess.pieces.PawnTest -->
    </test> <!-- Default test -->
  </suite> <!-- Default suite -->
</testng-results>
